Workbook

Sheet Dashboard
B2: Shareholding Pattern under Regulation 31 of SEBI (Listing Obligations and Disclosure Requirements) Regulations, 2015
C4: 1 | D4: Name of Listed Entity : | F4: (Name Of The Company)
C5: 2 | D5: Scrip Code/Name of Scrip/Class of Security : | G5: (Scrip Code/Name of Scrip/Class of Security)
C6: 3 | D6: Share Holding Pattern Filed under: Reg. 31(1)(a)/Reg. 31(1)(b)/Reg.31(1)(C ) | I6: SHAREHOLDING AS ON DATE
D7: a) If under 31(1)(b) then indicate the report for Quarter ending | I7: 46295
D8: b) If under 31(1)(c) then indicate date of allotment/extinguishment
C9: 4 | D9: Declaration: The Listed entity is required to submit the following declaration to the extent of submission of information:-
D11: S.No. | E11: Particulars | H11: Yes/No | I11: Promoter and Promoter Group | J11: Public shareholder | K11: Non Promoter- Non Public
D12: 1 | E12: Whether the Listed Entity has issued any partly paid up shares? | H12: No | I12: =IF('Table I'!$F$7<1,"-","Yes") -> - | J12: =IF('Table I'!$F$8<1,"-","Yes") -> - | K12: -
D13: 2 | E13: Whether the Listed Entity has issued any Convertible Securities ? | H13: =IF('Table I'!$N$12<1,"No","Yes") -> No | I13: =IF('Table I'!$N$7<1,"-","Yes") -> - | J13: =IF('Table I'!$N$8<1,"-","Yes") -> - | K13: -
D14: 3 | E14: Whether the Listed Entity has issued any Warrants ? | H14: =IF('Table I'!$O$12<1,"No","Yes") -> No | I14: =IF('Table I'!$O$7<1,"-","Yes") -> - | J14: =IF('Table I'!$O$8<1,"-","Yes") -> - | K14: -
D15: 4 | E15: Whether Listed Entity has granted any ESOPs, which are outstanding? | H15: =IF('Table I'!$P$12<1,"No","Yes") -> No | I15: =IF('Table I'!$P$7<1,"-","Yes") -> - | J15: =IF('Table I'!$P$8<1,"-","Yes") -> - | K15: -
D16: 5 | E16: Whether the Listed Entity has any shares against which depository receipts are issued? | H16: No | I16: - | J16: - | K16: -
D17: 6 | E17: Whether the Listed Entity has any shares in locked-in? | H17: =IF('Table I'!$T$12<1,"No","Yes") -> No | I17: =IF('Table I'!$T$7<1,"-","Yes") -> - | J17: =IF('Table I'!$T$8<1,"-","Yes") -> - | K17: -
D18: 7 | E18: Whether any shares held by promoters are encumbered under "Pledged"? | H18: =IF('Table I'!$V$7<1,"No","Yes") -> No | I18: =IF('Table I'!$V$7<1,"-","Yes") -> -
D19: 8 | E19: Whether any shares held by promoters are encumbered under "Non-Disposal Undertaking"? | H19: No | I19: -
D20: 9 | E20: Whether any shares held by promoters are encumbered, other than by way of Pledge or NDU, if any? | H20: No | I20: -
D21: 10 | E21: Whether company has equity shares with differential voting rights? | H21: No | I21: - | J21: - | K21: -
D22: 11 | E22: Whether the listed entity has any significant beneficial owner? | H22: No
C23: * If the Listed Entity selects the option ‘No’ for the questions above, the columns for the partly paid up shares, Outstanding Convertible Securities/Warrants, depository receipts, locked-in shares, No of shares pledged or otherwise encumbered by promoters, as applicable, shall not be displayed at the time of dissemination on the Stock Exchange website. Also wherever there is ‘No’ declared by Listed Entity in above table the values will be considered as ‘Zero’ by default on submission of the format of holding of specified securities.

Sheet Table I
B1: Table I - Summary Statement holding of specified securities
B3: Category | C3: Category of shareholder | D3: Number of shareholders | E3: No. of fully paid up equity shares held | F3: No. of Partly paid-up equity shares held | G3: No. of shares underlying Depository Receipts | H3: Total nos. shares held | I3: Shareholding as a % of total no. of shares (calculated as per SCRR, 1957) | J3: Number of Voting Rights held in each class of securities | N3: No. Of Shares Underlying Outstanding convertible securities | O3: No. of Shares Underlying Outstanding Warrants | P3: No. Of Outstanding ESOP Granted | Q3: No. of Shares Underlying Outstanding convertible securities, No. of Warrants and ESOP etc. | R3: Total No. of shares on fully diluted basis (including warrants, ESOP, Convertible Securities etc.) | S3: Shareholding , as a % assuming full conversion of convertible securities ( as a percentage of diluted share capital) | T3: Number of Locked in shares | V3: Number of Shares pledged | X3: Non-Disposal Undertaking | Z3: Other encumbrances, if any | AB3: Total Number of Shares encumbered | AD3: Number of equity shares held in dematerialized form | AE3: Sub-categorization of shares (XIX)
J4: No. of Voting Rights | M4: Total as a % (A+B+C) | T4: No. (a) | U4: As a % of total shares held (b) | V4: No. (a) | W4: As a % of total shares held (b) | X4: No. (a) | Y4: As a % of total shares held (b) | Z4: No. (a) | AA4: As a % of total shares held (b) | AB4: No. (a) | AC4: As a % of total shares held (b) | AE4: Shareholding (No. of shares) under
J5: Class X: EQUITY | K5: Class : Y | L5: Total | AE5: Sub-category (i) | AF5: Sub-category (ii) | AG5: Sub-category (iii)
B6: (I) | C6: (II) | D6: (III) | E6: (IV) | F6: (V) | G6: (VI) | H6: (VII) = (IV)+(V)+ (VI) | I6: (VIII) As a % of (A+B+C2) | J6: (IX) | N6: (XA) | O6: (XB) | P6: (XC) | Q6: (X) = (XA+XB+XC) | R6: (XI)=(VII+X) | S6: (XII)= (VII)+(X) As a % of (A+B+C2) | T6: (XIII) | V6: (XIV) | X6: (XV) | Z6: (XVI) | AB6: (XVII) = (XIV+XV+XVI) | AD6: (XVIII)
B7: (A) | C7: Promoter & Promoter Group | D7: ='Table II'!$E$36 -> 0 | E7: ='Table II'!$F$36 -> 0 | F7: 0 | G7: 0 | H7: =$G$7+$F$7+$E$7 -> 0 | I7: =IFERROR($H$7/$H$12*100,0) -> 0 | J7: =$H$7 -> 0 | K7: 0 | L7: =$J$7+$K$7 -> 0 | M7: =IFERROR(($L$7/$E$12*100),0) -> 0 | N7: ='Table II'!$O$36 -> 0 | O7: ='Table II'!$P$36 -> 0 | P7: ='Table II'!$Q$36 -> 0 | Q7: =$N$7+$O$7+$P$7 -> 0 | R7: =$Q$7+$H$7 -> 0 | S7: =IFERROR(($R$7/$R$12*100),0) -> 0 | T7: ='Table II'!$U$36 -> 0 | U7: =IFERROR(($T$7/$E$7*100),0) -> 0 | V7: ='Table II'!$W$36 -> 0 | W7: =IFERROR(($V$7/$E$7*100),0) -> 0 | X7: ='Table II'!$Y$36 -> 0 | Y7: =IFERROR(($X$7/$E$7*100),0) -> 0 | Z7: ='Table II'!$Y$36 -> 0 | AA7: =IFERROR(($Z$7/$E$7*100),0) -> 0 | AB7: =$V$7+$X$7+$Z$7 -> 0 | AC7: =IFERROR(($AB$7/$E$7*100),0) -> 0 | AD7: ='Table II'!$AE$36 -> 0
B8: (B) | C8: Public Shares | D8: ='Table III'!$D$94 -> 0 | E8: ='Table III'!$E$94 -> 0 | F8: 0 | G8: 0 | H8: =$G$8+$F$8+$E$8 -> 0 | I8: =IFERROR($H$8/$H$12*100,0) -> 0 | J8: =$H$8 -> 0 | K8: 0 | L8: =$J$8+$K$8 -> 0 | M8: =IFERROR(($L$8/$E$12*100),0) -> 0 | N8: ='Table III'!$N$94 -> 0 | O8: ='Table III'!$O$94 -> 0 | P8: ='Table III'!$P$94 -> 0 | Q8: =$N$8+$O$8+$P$8 -> 0 | R8: =$Q$8+$H$8 -> 0 | S8: =IFERROR(($R$8/$R$12*100),0) -> 0 | T8: ='Table III'!$T$94 -> 0 | U8: =IFERROR(($T$8/$E$8*100),0) -> 0 | AD8: ='Table III'!$AD$94 -> 0 | AE8: 0 | AF8: 0 | AG8: 0
B9: (C) | C9: Non- Promoter- None Public | D9: =$D$10+$D$11 -> 0 | E9: =$E$10+$E$11 -> 0 | F9: 0 | G9: 0 | H9: =$G$9+$F$9+$E$9 -> 0 | J9: =$H$9 -> 0 | K9: 0 | L9: =$J$9+$K$9 -> 0 | M9: =IFERROR(($L$9/$E$12*100),0) -> 0 | N9: =$N$10+$N$11 -> 0 | O9: =$O$10+$O$11 -> 0 | P9: =$P$10+$P$11 -> 0 | Q9: =$N$9+$O$9+$P$9 -> 0 | R9: =$Q$9+$H$9 -> 0 | T9: ='Table IV'!$T$9 -> 0 | U9: =IFERROR(($T$9/$E$9*100),0) -> 0 | AD9: =AD10+AD11 -> 0
B10: (C1) | C10: Shares underlying DRs | D10: 0 | E10: 0 | F10: 0 | G10: 0 | H10: =$G$10+$F$10+$E$10 -> 0 | J10: =$H$10 -> 0 | K10: 0 | L10: =$J$10+$K$10 -> 0 | M10: =IFERROR(($L$10/$E$12*100),0) -> 0 | N10: 0 | O10: 0 | P10: 0 | Q10: =$N$10+$O$10+$P$10 -> 0 | R10: =$Q$10+$H$10 -> 0 | T10: ='Table IV'!$T$7 -> 0 | U10: =IFERROR(($T$10/$E$10*100),0) -> 0 | AD10: ='Table IV'!$AD$7 -> 0
B11: (C2) | C11: Shares held by Employee Trusts | D11: 0 | E11: 0 | F11: 0 | G11: 0 | H11: =$G$11+$F$11+$E$11 -> 0 | I11: =IFERROR($H$11/$H$12*100,0) -> 0 | J11: =$H$11 -> 0 | K11: 0 | L11: =$J$11+$K$11 -> 0 | M11: =IFERROR(($L$11/$E$12*100),0) -> 0 | N11: 0 | O11: 0 | P11: 0 | Q11: =$N$11+$O$11+$P$11 -> 0 | R11: =$Q$11+$H$11 -> 0 | S11: =IFERROR(($R$11/$R$12*100),0) -> 0 | T11: ='Table IV'!$T$8 -> 0 | U11: =IFERROR(($T$11/$E$11*100),0) -> 0 | AD11: ='Table IV'!$AD$8 -> 0
B12: Total | D12: =SUM($D$7:$D$9) -> 0 | E12: =SUM($E$7:$E$9) -> 0 | F12: =SUM($F$7:$F$9) -> 0 | G12: =SUM($G$7:$G$9) -> 0 | H12: =$G$12+$F$12+$E$12 -> 0 | I12: =SUM($I$7+$I$8+$I$11) -> 0 | J12: =SUM($J$7:$J$9) -> 0 | K12: =SUM($K$7:$K$9) -> 0 | L12: =SUM($L$7:$L$9) -> 0 | M12: =IFERROR(($L$12/$E$12*100),0) -> 0 | N12: =SUM($N$7:$N$9) -> 0 | O12: =SUM($O$7:$O$9) -> 0 | P12: =SUM($P$7:$P$9) -> 0 | Q12: =SUM($Q$7:$Q$9) -> 0 | R12: =$Q$12+$H$12 -> 0 | S12: =$S$7+$S$8+$S$11 -> 0 | T12: =SUM($T$7:$T$9) -> 0 | U12: =IFERROR(($T$12/$E$12*100),0) -> 0 | V12: =SUM($V$7) -> 0 | W12: =IFERROR(($V$12/$E$12*100),0) -> 0 | X12: =SUM($X$7) -> 0 | Y12: =IFERROR(($X$12/$E$12*100),0) -> 0 | Z12: =SUM($Z$7) -> 0 | AA12: =IFERROR(($Z$12/$E$12*100),0) -> 0 | AB12: =$V$12+$X$12+$Z$12 -> 0 | AC12: =IFERROR(($AB$12/$E$12*100),0) -> 0 | AD12: =SUM($AD$7:$AD$9) -> 0 | AE12: =SUM($AE$8) -> 0 | AF12: =SUM($AF$8) -> 0 | AG12: =SUM($AG$8) -> 0

Sheet Table II
A1: Table II - Statement showing shareholding pattern of the Promoter and Promoter Group
A3: (A) | B3: Category & Name of shareholders | C3: Entity type i.e. promoter OR promoter group entity (except promoter) | D3: PAN | E3: No. of Shareholders | F3: No. of Fully paid up equity shares held | G3: Partly paid-up equity shares held | H3: No. of shares underlying Depository Receipts | I3: Total nos. shares held | J3: Shareholding as a % of total no. of shares (calculated as per SCRR, 1957) | K3: Number of Voting Rights held in each class of securities | O3: No. Of Shares Underlying Outstanding convertible securities | P3: No. of Shares Underlying Outstanding Warrants | Q3: No. Of Outstanding ESOP Granted | R3: No. of Shares Underlying Outstanding convertible securities, No. of Warrants and ESOP etc. | S3: Total No. of shares on fully diluted basis (including warrants, ESOP, Convertible Securities etc.) | T3: Shareholding , as a % assuming full conversion of convertible securities ( as a percentage of diluted share capital) | U3: Number of Locked in shares | W3: Number of Shares pledged | Y3: Non-Disposal Undertaking | AA3: Other encumbrances, if any | AC3: Total Number of Shares encumbered | AE3: Number of equity shares held in dematerialized form | AF3: Sub-categorization of shares (XIX)
K4: No. of Voting Rights | N4: Total as a % of Total Voting Rights | U4: No. (a) | V4: As a % of total shares held (b) | W4: No. (a) | X4: As a % of total shares held (b) | Y4: No. (a) | Z4: As a % of total shares held (b) | AA4: No. (a) | AB4: As a % of total shares held (b) | AC4: No. (a) | AD4: As a % of total shares held (b) | AF4: Shareholding (No. of shares) under
K5: Class : e.g. X | L5: Class : e.g. Y | M5: Total | AF5: Sub-category (i) | AG5: Sub-category (ii) | AH5: Sub-category (iii)
B6: (I) | D6: (II) | E6: (III) | F6: (IV) | G6: (V) | H6: (VI) | I6: (VII) = (IV)+(V)+ (VI) | J6: (VIII) As a % of (A+B+C2) | K6: (IX) | O6: (XA) | P6: (XB) | Q6: (XC) | R6: (X) = (XA+XB+XC) | S6: (XI)=(VII+X) | T6: (XII)= (VII)+(X) As a % of (A+B+C2) | U6: (XIII) | W6: (XIV) | Y6: (XV) | AA6: (XVI) | AC6: (XVII) = (XIV+XV+XVI) | AE6: (XVIII)
A7: ( 1 ) | B7: Indian
A8: (a) | B8: Individuals/Hindu undivided Family | C8: - | D8: - | E8: 0 | F8: 0 | G8: 0 | H8: 0 | I8: =$F$8+$G$8+$H$8 -> 0 | J8: =IFERROR($I$8/'Table I'!$E$12*100,0) -> 0 | K8: =$I$8 -> 0 | L8: 0 | M8: =$K$8+$L$8 -> 0 | N8: =IFERROR($M$8/'Table I'!$E$12*100,0) -> 0 | O8: 0 | P8: 0 | Q8: 0 | R8: =$O$8+$P$8+$Q$8 -> 0 | S8: =$R$8+$I$8 -> 0 | T8: =IFERROR(($S$8/'Table I'!$R$12*100),0) -> 0 | U8: 0 | V8: =IFERROR($U$8/$F$8*100,0) -> 0 | W8: 0 | X8: =IFERROR(($W$8/$F$8*100),0) -> 0 | Y8: 0 | Z8: =IFERROR(($Y$8/$F$8*100),0) -> 0 | AA8: 0 | AB8: =IFERROR(($AA$8/$F$8*100),0) -> 0 | AC8: =$W$8+$Y$8+$AA$8 -> 0 | AD8: =IFERROR(($AC$8/$F$8*100),0) -> 0 | AE8: 0
A9: (b) | B9: Central Government/ State Government(s) | C9: - | D9: - | E9: 0 | F9: 0 | G9: 0 | H9: 0 | I9: =$F$9+$G$9+$H$9 -> 0 | J9: =IFERROR($I$9/'Table I'!$E$12*100,0) -> 0 | K9: =$I$9 -> 0 | L9: 0 | M9: =$K$9+$L$9 -> 0 | N9: =IFERROR($M$9/'Table I'!$E$12*100,0) -> 0 | O9: 0 | P9: 0 | Q9: 0 | R9: =$O$9+$P$9+$Q$9 -> 0 | S9: =$R$9+$I$9 -> 0 | T9: =IFERROR(($S$9/'Table I'!$R$12*100),0) -> 0 | U9: 0 | V9: =IFERROR($U$9/$F$9*100,0) -> 0 | W9: 0 | X9: =IFERROR(($W$9/$F$9*100),0) -> 0 | Y9: 0 | Z9: =IFERROR(($Y$9/$F$9*100),0) -> 0 | AA9: 0 | AB9: =IFERROR(($AA$9/$F$9*100),0) -> 0 | AC9: =$W$9+$Y$9+$AA$9 -> 0 | AD9: =IFERROR(($AC$9/$F$9*100),0) -> 0 | AE9: 0
A10: (c) | B10: Financial Institutions/ Banks | C10: - | D10: - | E10: 0 | F10: 0 | G10: 0 | H10: 0 | I10: =$F$10+$G$10+$H$10 -> 0 | J10: =IFERROR($I$10/'Table I'!$E$12*100,0) -> 0 | K10: =$I$10 -> 0 | L10: 0 | M10: =$K$10+$L$10 -> 0 | N10: =IFERROR($M$10/'Table I'!$E$12*100,0) -> 0 | O10: 0 | P10: 0 | Q10: 0 | R10: =$O$10+$P$10+$Q$10 -> 0 | S10: =$R$10+$I$10 -> 0 | T10: =IFERROR(($S$10/'Table I'!$R$12*100),0) -> 0 | U10: 0 | V10: =IFERROR($U$10/$F$10*100,0) -> 0 | W10: 0 | X10: =IFERROR(($W$10/$F$10*100),0) -> 0 | Y10: 0 | Z10: =IFERROR(($Y$10/$F$10*100),0) -> 0 | AA10: 0 | AB10: =IFERROR(($AA$10/$F$10*100),0) -> 0 | AC10: =$W$10+$Y$10+$AA$10 -> 0 | AD10: =IFERROR(($AC$10/$F$10*100),0) -> 0 | AE10: 0
A11: (d) | B11: Any Other (specify) | C11: - | D11: - | E11: =$E$12+$E$13+$E$14+$E$15+$E$16+$E$17 -> 0 | F11: =$F$12+$F$13+$F$14+$F$15+$F$16+$F$17 -> 0 | G11: =$G$12+$G$13+$G$14+$G$15+$G$16+$G$17 -> 0 | H11: =$H$12+$H$13+$H$14+$H$15+$H$16+$H$17 -> 0 | I11: =$F$11+$G$11+$H$11 -> 0 | J11: =IFERROR($I$11/'Table I'!$E$12*100,0) -> 0 | K11: =$I$11 -> 0 | L11: =$L$12+$L$13+$L$14+$L$15+$L$16+$L$17 -> 0 | M11: =$K$11+$L$11 -> 0 | N11: =IFERROR($M$11/'Table I'!$E$12*100,0) -> 0 | O11: =$O$12+$O$13+$O$14+$O$15+$O$16+$O$17 -> 0 | P11: =$P$12+$P$13+$P$14+$P$15+$P$16+$P$17 -> 0 | Q11: =$Q$12+$Q$13+$Q$14+$Q$15+$Q$16+$Q$17 -> 0 | R11: =$O$11+$P$11+$Q$11 -> 0 | S11: =$R$11+$I$11 -> 0 | T11: =IFERROR(($S$11/'Table I'!$R$12*100),0) -> 0 | U11: =$U$12+$U$13+$U$14+$U$15+$U$16+$U$17 -> 0 | V11: =IFERROR($U$11/$F$11*100,0) -> 0 | W11: =$W$12+$W$13+$W$14+$W$15+$W$16+$W$17 -> 0 | X11: =IFERROR(($W$11/$F$11*100),0) -> 0 | Y11: =$Y$12+$Y$13+$Y$14+$Y$15+$Y$16+$Y$17 -> 0 | Z11: =IFERROR(($Y$11/$F$11*100),0) -> 0 | AA11: =$AA$12+$AA$13+$AA$14+$AA$15+$AA$16+$AA$17 -> 0 | AB11: =IFERROR(($AA$11/$F$11*100),0) -> 0 | AC11: =$W$11+$Y$11+$AA$11 -> 0 | AD11: =IFERROR(($AC$11/$F$11*100),0) -> 0 | AE11: 0
B12: Director or Director's Relatives | C12: - | D12: - | E12: 0 | F12: 0 | G12: 0 | H12: 0 | I12: =$F$12+$G$12+$H$12 -> 0 | J12: =IFERROR($I$12/'Table I'!$E$12*100,0) -> 0 | K12: =$I$12 -> 0 | L12: 0 | M12: =$K$12+$L$12 -> 0 | N12: =IFERROR($M$12/'Table I'!$E$12*100,0) -> 0 | O12: 0 | P12: 0 | Q12: 0 | R12: =$O$12+$P$12+$Q$12 -> 0 | S12: =$R$12+$I$12 -> 0 | T12: =IFERROR(($S$12/'Table I'!$R$12*100),0) -> 0 | U12: 0 | V12: =IFERROR($U$12/F12*100,0) -> 0 | W12: 0 | X12: =IFERROR(($W$12/$F$12*100),0) -> 0 | Y12: 0 | Z12: =IFERROR(($Y$12/$F$12*100),0) -> 0 | AA12: 0 | AB12: =IFERROR(($AA$12/$F$12*100),0) -> 0 | AC12: =$W$12+$Y$12+$AA$12 -> 0 | AD12: =IFERROR(($AC$12/$F$12*100),0) -> 0 | AE12: 0
B13: Bodies Corporate | C13: - | D13: - | E13: 0 | F13: 0 | G13: 0 | H13: 0 | I13: =$F$13+$G$13+$H$13 -> 0 | J13: =IFERROR($I$13/'Table I'!$E$12*100,0) -> 0 | K13: =$I$13 -> 0 | L13: 0 | M13: =$K$13+$L$13 -> 0 | N13: =IFERROR($M$13/'Table I'!$E$12*100,0) -> 0 | O13: 0 | P13: 0 | Q13: 0 | R13: =$O$13+$P$13+$Q$13 -> 0 | S13: =$R$13+$I$13 -> 0 | T13: =IFERROR(($S$13/'Table I'!$R$12*100),0) -> 0 | U13: 0 | V13: =IFERROR($U$13/F13*100,0) -> 0 | W13: 0 | X13: =IFERROR(($W$13/$F$13*100),0) -> 0 | Y13: 0 | Z13: =IFERROR(($Y$13/$F$13*100),0) -> 0 | AA13: 0 | AB13: =IFERROR(($AA$13/$F$13*100),0) -> 0 | AC13: =$W$13+$Y$13+$AA$13 -> 0 | AD13: =IFERROR(($AC$13/$F$13*100),0) -> 0 | AE13: 0
B14: Trusts | C14: - | D14: - | E14: 0 | F14: 0 | G14: 0 | H14: 0 | I14: =$F$14+$G$14+$H$14 -> 0 | J14: =IFERROR($I$14/'Table I'!$E$12*100,0) -> 0 | K14: =$I$14 -> 0 | L14: 0 | M14: =$K$14+$L$14 -> 0 | N14: =IFERROR($M$14/'Table I'!$E$12*100,0) -> 0 | O14: 0 | P14: 0 | Q14: 0 | R14: =$O$14+$P$14+$Q$14 -> 0 | S14: =$R$14+$I$14 -> 0 | T14: =IFERROR(($S$14/'Table I'!$R$12*100),0) -> 0 | U14: 0 | V14: =IFERROR($U$14/F14*100,0) -> 0 | W14: 0 | X14: =IFERROR(($W$14/$F$14*100),0) -> 0 | Y14: 0 | Z14: =IFERROR(($Y$14/$F$14*100),0) -> 0 | AA14: 0 | AB14: =IFERROR(($AA$14/$F$14*100),0) -> 0 | AC14: =$W$14+$Y$14+$AA$14 -> 0 | AD14: =IFERROR(($AC$14/$F$14*100),0) -> 0 | AE14: 0
B15: Partnership Firms | C15: - | D15: - | E15: 0 | F15: 0 | G15: 0 | H15: 0 | I15: =$F$15+$G$15+$H$15 -> 0 | J15: =IFERROR($I$15/'Table I'!$E$12*100,0) -> 0 | K15: =$I$15 -> 0 | L15: 0 | M15: =$K$15+$L$15 -> 0 | N15: =IFERROR($M$15/'Table I'!$E$12*100,0) -> 0 | O15: 0 | P15: 0 | Q15: 0 | R15: =$O$15+$P$15+$Q$15 -> 0 | S15: =$R$15+$I$15 -> 0 | T15: =IFERROR(($S$15/'Table I'!$R$12*100),0) -> 0 | U15: 0 | V15: =IFERROR($U$15/F15*100,0) -> 0 | W15: 0 | X15: =IFERROR(($W$15/$F$15*100),0) -> 0 | Y15: 0 | Z15: =IFERROR(($Y$15/$F$15*100),0) -> 0 | AA15: 0 | AB15: =IFERROR(($AA$15/$F$15*100),0) -> 0 | AC15: =$W$15+$Y$15+$AA$15 -> 0 | AD15: =IFERROR(($AC$15/$F$15*100),0) -> 0 | AE15: 0
B16: Person Acting in Concert | C16: - | D16: - | E16: 0 | F16: 0 | G16: 0 | H16: 0 | I16: =$F$16+$G$16+$H$16 -> 0 | J16: =IFERROR($I$16/'Table I'!$E$12*100,0) -> 0 | K16: =$I$16 -> 0 | L16: 0 | M16: =$K$16+$L$16 -> 0 | N16: =IFERROR($M$16/'Table I'!$E$12*100,0) -> 0 | O16: 0 | P16: 0 | Q16: 0 | R16: =$O$16+$P$16+$Q$16 -> 0 | S16: =$R$16+$I$16 -> 0 | T16: =IFERROR(($S$16/'Table I'!$R$12*100),0) -> 0 | U16: 0 | V16: =IFERROR($U$16/F16*100,0) -> 0 | W16: 0 | X16: =IFERROR(($W$16/$F$16*100),0) -> 0 | Y16: 0 | Z16: =IFERROR(($Y$16/$F$16*100),0) -> 0 | AA16: 0 | AB16: =IFERROR(($AA$16/$F$16*100),0) -> 0 | AC16: =$W$16+$Y$16+$AA$16 -> 0 | AD16: =IFERROR(($AC$16/$F$16*100),0) -> 0 | AE16: 0
B17: Other | C17: - | D17: - | E17: 0 | F17: 0 | G17: 0 | H17: 0 | I17: =$F$17+$G$17+$H$17 -> 0 | J17: =IFERROR($I$17/'Table I'!$E$12*100,0) -> 0 | K17: =$I$17 -> 0 | L17: 0 | M17: =$K$17+$L$17 -> 0 | N17: =IFERROR($M$17/'Table I'!$E$12*100,0) -> 0 | O17: 0 | P17: 0 | Q17: 0 | R17: =$O$17+$P$17+$Q$17 -> 0 | S17: =$R$17+$I$17 -> 0 | T17: =IFERROR(($S$17/'Table I'!$R$12*100),0) -> 0 | U17: 0 | V17: =IFERROR($U$17/F17*100,0) -> 0 | W17: 0 | X17: =IFERROR(($W$17/$F$17*100),0) -> 0 | Y17: 0 | Z17: =IFERROR(($Y$17/$F$17*100),0) -> 0 | AA17: 0 | AB17: =IFERROR(($AA$17/$F$17*100),0) -> 0 | AC17: =$W$17+$Y$17+$AA$17 -> 0 | AD17: =IFERROR(($AC$17/$F$17*100),0) -> 0 | AE17: 0
B18: Sub. Total (A)(1) | C18: - | D18: - | E18: =$E$11+$E$10+$E$9+$E$8 -> 0 | F18: =$F$11+$F$10+$F$9+$F$8 -> 0 | G18: =$G$8+$G$9+$G$10+$G$11 -> 0 | H18: =$H$8+$H$9+$H$10+$H$11 -> 0 | I18: =$F$18+$G$18+$H$18 -> 0 | J18: =IFERROR($I$18/'Table I'!$E$12*100,0) -> 0 | K18: =$I$18 -> 0 | L18: =$L$8+$L$9+$L$10+$L$11 -> 0 | M18: =$K$18+$L$18 -> 0 | N18: =IFERROR($M$18/'Table I'!$E$12*100,0) -> 0 | O18: =$O$8+$O$9+$O$10+$O$11 -> 0 | P18: =$P$8+$P$9+$P$10+$P$11 -> 0 | Q18: =$Q$8+$Q$9+$Q$10+$Q$11 -> 0 | R18: =$O$18+$P$18+$Q$18 -> 0 | S18: =$R$18+$I$18 -> 0 | T18: =IFERROR(($S$18/'Table I'!$R$12*100),0) -> 0 | U18: =$U$11+$U$10+$U$9+$U$8 -> 0 | V18: =IFERROR($U$18/$F$18*100,0) -> 0 | W18: =$W$8+$W$9+$W$10+$W$11 -> 0 | X18: =IFERROR(($W$18/$F$18*100),0) -> 0 | Y18: =$Y$8+$Y$9+$Y$10+$Y$11 -> 0 | Z18: =IFERROR(($Y$18/$F$18*100),0) -> 0 | AA18: =$AA$8+$AA$9+$AA$10+$AA$11 -> 0 | AB18: =IFERROR(($AA$18/$F$18*100),0) -> 0 | AC18: =$W$18+$Y$18+$AA$18 -> 0 | AD18: =IFERROR(($AC$18/$F$18*100),0) -> 0 | AE18: =$AE$8+$AE$9+$AE$10+AE11 -> 0
A19: ( 2 ) | B19: Foreign
A20: (a) | B20: Individuals (NonResident Individuals/ Foreign Individuals) | C20: - | D20: - | E20: 0 | F20: 0 | G20: 0 | H20: 0 | I20: =$F$20+$G$20+$H$20 -> 0 | J20: =IFERROR($I$20/'Table I'!$E$12*100,0) -> 0 | K20: =$I$20 -> 0 | L20: 0 | M20: =$K$20+$L$20 -> 0 | N20: =IFERROR($M$20/'Table I'!$E$12*100,0) -> 0 | O20: 0 | P20: 0 | Q20: 0 | R20: =$O$20+$P$20+$Q$20 -> 0 | S20: =$R$20+$I$20 -> 0 | T20: =IFERROR(($S$20/'Table I'!$R$12*100),0) -> 0 | U20: 0 | V20: =IFERROR($U$20/$F$20*100,0) -> 0 | W20: 0 | X20: =IFERROR(($W$20/$F$20*100),0) -> 0 | Y20: 0 | Z20: =IFERROR(($Y$20/$F$20*100),0) -> 0 | AA20: 0 | AB20: =IFERROR(($AA$20/$F$20*100),0) -> 0 | AC20: =$W$20+$Y$20+$AA$20 -> 0 | AD20: =IFERROR(($AC$20/$F$20*100),0) -> 0 | AE20: 0
A21: (b) | B21: Government | C21: - | D21: - | E21: 0 | F21: 0 | G21: 0 | H21: 0 | I21: =$F$21+$G$21+$H$21 -> 0 | J21: =IFERROR($I$21/'Table I'!$E$12*100,0) -> 0 | K21: =$I$21 -> 0 | L21: 0 | M21: =$K$21+$L$21 -> 0 | N21: =IFERROR($M$21/'Table I'!$E$12*100,0) -> 0 | O21: 0 | P21: 0 | Q21: 0 | R21: =$O$21+$P$21+$Q$21 -> 0 | S21: =$R$21+$I$21 -> 0 | T21: =IFERROR(($S$21/'Table I'!$R$12*100),0) -> 0 | U21: 0 | V21: =IFERROR($U$21/$F$21*100,0) -> 0 | W21: 0 | X21: =IFERROR(($W$21/$F$21*100),0) -> 0 | Y21: 0 | Z21: =IFERROR(($Y$21/$F$21*100),0) -> 0 | AA21: 0 | AB21: =IFERROR(($AA$21/$F$21*100),0) -> 0 | AC21: =$W$21+$Y$21+$AA$21 -> 0 | AD21: =IFERROR(($AC$21/$F$21*100),0) -> 0 | AE21: 0
A22: (c) | B22: Institutions | C22: - | D22: - | E22: 0 | F22: 0 | G22: 0 | H22: 0 | I22: =$F$22+$G$22+$H$22 -> 0 | J22: =IFERROR($I$22/'Table I'!$E$12*100,0) -> 0 | K22: =$I$22 -> 0 | L22: 0 | M22: =$K$22+$L$22 -> 0 | N22: =IFERROR($M$22/'Table I'!$E$12*100,0) -> 0 | O22: 0 | P22: 0 | Q22: 0 | R22: =$O$22+$P$22+$Q$22 -> 0 | S22: =$R$22+$I$22 -> 0 | T22: =IFERROR(($S$22/'Table I'!$R$12*100),0) -> 0 | U22: 0 | V22: =IFERROR($U$22/$F$22*100,0) -> 0 | W22: 0 | X22: =IFERROR(($W$22/$F$22*100),0) -> 0 | Y22: 0 | Z22: =IFERROR(($Y$22/$F$22*100),0) -> 0 | AA22: 0 | AB22: =IFERROR(($AA$22/$F$22*100),0) -> 0 | AC22: =$W$22+$Y$22+$AA$22 -> 0 | AD22: =IFERROR(($AC$22/$F$22*100),0) -> 0 | AE22: 0
A23: (d) | B23: Foreign Portfolio Investor | C23: - | D23: - | E23: 0 | F23: 0 | G23: 0 | H23: 0 | I23: =$F$23+$G$23+$H$23 -> 0 | J23: =IFERROR($I$23/'Table I'!$E$12*100,0) -> 0 | K23: =$I$23 -> 0 | L23: 0 | M23: =$K$23+$L$23 -> 0 | N23: =IFERROR($M$23/'Table I'!$E$12*100,0) -> 0 | O23: 0 | P23: 0 | Q23: 0 | R23: =$O$23+$P$23+$Q$23 -> 0 | S23: =$R$23+$I$23 -> 0 | T23: =IFERROR(($S$23/'Table I'!$R$12*100),0) -> 0 | U23: 0 | V23: =IFERROR($U$23/$F$23*100,0) -> 0 | W23: 0 | X23: =IFERROR(($W$23/$F$23*100),0) -> 0 | Y23: 0 | Z23: =IFERROR(($Y$23/$F$23*100),0) -> 0 | AA23: 0 | AB23: =IFERROR(($AA$23/$F$23*100),0) -> 0 | AC23: =$W$23+$Y$23+$AA$23 -> 0 | AD23: =IFERROR(($AC$23/$F$23*100),0) -> 0 | AE23: 0
A24: (e) | B24: Any Other (specify) | C24: - | D24: - | E24: =$E$25+$E$26+$E$27+$E$28+$E$29+$E$30+$E$31+$E$32+$E$33+$E$34 -> 0 | F24: =$F$25+$F$26+$F$27+$F$28+$F$29+$F$30+F31+F32+F33+F34 -> 0 | G24: =$G$25+$G$26+$G$27+$G$28+$G$29+$G$30+$G$31+$G$32+$G$33+$G$34 -> 0 | H24: =$H$25+$H$26+$H$27+$H$28+$H$29+$H$30+$H$31+$H$32+$H$33+$H$34 -> 0 | I24: =$F$24+$G$24+$H$24 -> 0 | J24: =IFERROR($I$24/'Table I'!$E$12*100,0) -> 0 | K24: =$I$24 -> 0 | L24: =$L$25+$L$26+$L$27+$L$28+$L$29+$L$30+$L$31+$L$32+$L$33+$L$34 -> 0 | M24: =$K$24+$L$24 -> 0 | N24: =IFERROR($M$24/'Table I'!$E$12*100,0) -> 0 | O24: =$O$25+$O$26+$O$27+$O$28+$O$29+$O$30+$O$31+$O$32+$O$33+$O$34 -> 0 | P24: =$P$25+$P$26+$P$27+$P$28+$P$29+$P$30+$P$31+$P$32+$P$33+$P$34 -> 0 | Q24: =$Q$25+$Q$26+$Q$27+$Q$28+$Q$29+$Q$30+$Q$31+$Q$32+$Q$33+$Q$34 -> 0 | R24: =$O$24+$P$24+$Q$24 -> 0 | S24: =$R$24+$I$24 -> 0 | T24: =IFERROR(($S$24/'Table I'!$R$12*100),0) -> 0 | U24: =$U$25+$U$26+$U$27+$U$28+$U$29+$U$30+$U$31+$U$32+$U$33+$U$34 -> 0 | V24: =IFERROR($U$24/$F$24*100,0) -> 0 | W24: =$W$25+$W$26+$W$27+$W$28+$W$29+$W$30+$W$31+$W$32+$W$33+$W$34 -> 0 | X24: =IFERROR(($W$24/$F$24*100),0) -> 0 | Y24: =$Y$25+$Y$26+$Y$27+$Y$28+$Y$29+$Y$30+$Y$31+$Y$32+$Y$33+$Y$34 -> 0 | Z24: =IFERROR(($Y$24/$F$24*100),0) -> 0 | AA24: =$AA$25+$AA$26+$AA$27+$AA$28+$AA$29+$AA$30+$AA$31+$AA$32+$AA$33+$AA$34 -> 0 | AB24: =IFERROR(($AA$24/$F$24*100),0) -> 0 | AC24: =$W$24+$Y$24+$AA$24 -> 0 | AD24: =IFERROR(($AC$24/$F$24*100),0) -> 0 | AE24: 0
B25: Bodies Corporate | C25: - | D25: - | E25: 0 | F25: 0 | G25: 0 | H25: 0 | I25: =$F$25+$G$25+$H$25 -> 0 | J25: =IFERROR($I$25/'Table I'!$E$12*100,0) -> 0 | K25: =$I$25 -> 0 | L25: 0 | M25: =$K$25+$L$25 -> 0 | N25: =IFERROR($M$25/'Table I'!$E$12*100,0) -> 0 | O25: 0 | P25: 0 | Q25: 0 | R25: =$O$25+$P$25+$Q$25 -> 0 | S25: =$R$25+$I$25 -> 0 | T25: =IFERROR(($S$25/'Table I'!$R$12*100),0) -> 0 | U25: 0 | V25: =IFERROR($U$25/$F$25*100,0) -> 0 | W25: 0 | X25: =IFERROR(($W$25/$F$25*100),0) -> 0 | Y25: 0 | Z25: =IFERROR(($Y$25/$F$25*100),0) -> 0 | AA25: 0 | AB25: =IFERROR(($AA$25/$F$25*100),0) -> 0 | AC25: =$W$25+$Y$25+$AA$25 -> 0 | AD25: =IFERROR(($AC$25/$F$25*100),0) -> 0 | AE25: 0
B26: Clearing Member | C26: - | D26: - | E26: 0 | F26: 0 | G26: 0 | H26: 0 | I26: =$F$26+$G$26+$H$26 -> 0 | J26: =IFERROR($I$26/'Table I'!$E$12*100,0) -> 0 | K26: =$I$26 -> 0 | L26: 0 | M26: =$K$26+$L$26 -> 0 | N26: =IFERROR($M$26/'Table I'!$E$12*100,0) -> 0 | O26: 0 | P26: 0 | Q26: 0 | R26: =$O$26+$P$26+$Q$26 -> 0 | S26: =$R$26+$I$26 -> 0 | T26: =IFERROR(($S$26/'Table I'!$R$12*100),0) -> 0 | U26: 0 | V26: =IFERROR($U$26/$F$26*100,0) -> 0 | W26: 0 | X26: =IFERROR(($W$26/$F$26*100),0) -> 0 | Y26: 0 | Z26: =IFERROR(($Y$26/$F$26*100),0) -> 0 | AA26: 0 | AB26: =IFERROR(($AA$26/$F$26*100),0) -> 0 | AC26: =$W$26+$Y$26+$AA$26 -> 0 | AD26: =IFERROR(($AC$26/$F$26*100),0) -> 0 | AE26: 0
B27: Employee Welfare Fund | C27: - | D27: - | E27: 0 | F27: 0 | G27: 0 | H27: 0 | I27: =$F$27+$G$27+$H$27 -> 0 | J27: =IFERROR($I$27/'Table I'!$E$12*100,0) -> 0 | K27: =$I$27 -> 0 | L27: 0 | M27: =$K$27+$L$27 -> 0 | N27: =IFERROR($M$27/'Table I'!$E$12*100,0) -> 0 | O27: 0 | P27: 0 | Q27: 0 | R27: =$O$27+$P$27+$Q$27 -> 0 | S27: =$R$27+$I$27 -> 0 | T27: =IFERROR(($S$27/'Table I'!$R$12*100),0) -> 0 | U27: 0 | V27: =IFERROR($U$27/$F$27*100,0) -> 0 | W27: 0 | X27: =IFERROR(($W$27/$F$27*100),0) -> 0 | Y27: 0 | Z27: =IFERROR(($Y$27/$F$27*100),0) -> 0 | AA27: 0 | AB27: =IFERROR(($AA$27/$F$27*100),0) -> 0 | AC27: =$W$27+$Y$27+$AA$27 -> 0 | AD27: =IFERROR(($AC$27/$F$27*100),0) -> 0 | AE27: 0
B28: Firms | C28: - | D28: - | E28: 0 | F28: 0 | G28: 0 | H28: 0 | I28: =$F$28+$G$28+$H$28 -> 0 | J28: =IFERROR($I$28/'Table I'!$E$12*100,0) -> 0 | K28: =$I$28 -> 0 | L28: 0 | M28: =$K$28+$L$28 -> 0 | N28: =IFERROR($M$28/'Table I'!$E$12*100,0) -> 0 | O28: 0 | P28: 0 | Q28: 0 | R28: =$O$28+$P$28+$Q$28 -> 0 | S28: =$R$28+$I$28 -> 0 | T28: =IFERROR(($S$28/'Table I'!$R$12*100),0) -> 0 | U28: 0 | V28: =IFERROR($U$28/$F$28*100,0) -> 0 | W28: 0 | X28: =IFERROR(($W$28/$F$28*100),0) -> 0 | Y28: 0 | Z28: =IFERROR(($Y$28/$F$28*100),0) -> 0 | AA28: 0 | AB28: =IFERROR(($AA$28/$F$28*100),0) -> 0 | AC28: =$W$28+$Y$28+$AA$28 -> 0 | AD28: =IFERROR(($AC$28/$F$28*100),0) -> 0 | AE28: 0
B29: Other | C29: - | D29: - | E29: 0 | F29: 0 | G29: 0 | H29: 0 | I29: =$F$29+$G$29+$H$29 -> 0 | J29: =IFERROR($I$29/'Table I'!$E$12*100,0) -> 0 | K29: =$I$29 -> 0 | L29: 0 | M29: =$K$29+$L$29 -> 0 | N29: =IFERROR($M$29/'Table I'!$E$12*100,0) -> 0 | O29: 0 | P29: 0 | Q29: 0 | R29: =$O$29+$P$29+$Q$29 -> 0 | S29: =$R$29+$I$29 -> 0 | T29: =IFERROR(($S$29/'Table I'!$R$12*100),0) -> 0 | U29: 0 | V29: =IFERROR($U$29/$F$29*100,0) -> 0 | W29: 0 | X29: =IFERROR(($W$29/$F$29*100),0) -> 0 | Y29: 0 | Z29: =IFERROR(($Y$29/$F$29*100),0) -> 0 | AA29: 0 | AB29: =IFERROR(($AA$29/$F$29*100),0) -> 0 | AC29: =$W$29+$Y$29+$AA$29 -> 0 | AD29: =IFERROR(($AC$29/$F$29*100),0) -> 0 | AE29: 0
B30: Overseas Corporate Bodies | C30: - | D30: - | E30: 0 | F30: 0 | G30: 0 | H30: 0 | I30: =$F$30+$G$30+$H$30 -> 0 | J30: =IFERROR($I$30/'Table I'!$E$12*100,0) -> 0 | K30: =$I$30 -> 0 | L30: 0 | M30: =$K$30+$L$30 -> 0 | N30: =IFERROR($M$30/'Table I'!$E$12*100,0) -> 0 | O30: 0 | P30: 0 | Q30: 0 | R30: =$O$30+$P$30+$Q$30 -> 0 | S30: =$R$30+$I$30 -> 0 | T30: =IFERROR(($S$30/'Table I'!$R$12*100),0) -> 0 | U30: 0 | V30: =IFERROR($U$30/$F$30*100,0) -> 0 | W30: 0 | X30: =IFERROR(($W$30/$F$30*100),0) -> 0 | Y30: 0 | Z30: =IFERROR(($Y$30/$F$30*100),0) -> 0 | AA30: 0 | AB30: =IFERROR(($AA$30/$F$30*100),0) -> 0 | AC30: =$W$30+$Y$30+$AA$30 -> 0 | AD30: =IFERROR(($AC$30/$F$30*100),0) -> 0 | AE30: 0
B31: Private Equity Fund | C31: - | D31: - | E31: 0 | F31: 0 | G31: 0 | H31: 0 | I31: =$F$31+$G$31+$H$31 -> 0 | J31: =IFERROR($I$31/'Table I'!$E$12*100,0) -> 0 | K31: =$I$31 -> 0 | L31: 0 | M31: =$K$31+$L$31 -> 0 | N31: =IFERROR($M$31/'Table I'!$E$12*100,0) -> 0 | O31: 0 | P31: 0 | Q31: 0 | R31: =$O$31+$P$31+$Q$31 -> 0 | S31: =$R$31+$I$31 -> 0 | T31: =IFERROR(($S$31/'Table I'!$R$12*100),0) -> 0 | U31: 0 | V31: =IFERROR($U$31/$F$31*100,0) -> 0 | W31: 0 | X31: =IFERROR(($W$31/$F$31*100),0) -> 0 | Y31: 0 | Z31: =IFERROR(($Y$31/$F$31*100),0) -> 0 | AA31: 0 | AB31: =IFERROR(($AA$31/$F$31*100),0) -> 0 | AC31: =$W$31+$Y$31+$AA$31 -> 0 | AD31: =IFERROR(($AC$31/$F$31*100),0) -> 0 | AE31: 0
B32: Societies | C32: - | D32: - | E32: 0 | F32: 0 | G32: 0 | H32: 0 | I32: =$F$32+$G$32+$H$32 -> 0 | J32: =IFERROR($I$32/'Table I'!$E$12*100,0) -> 0 | K32: =$I$32 -> 0 | L32: 0 | M32: =$K$32+$L$32 -> 0 | N32: =IFERROR($M$32/'Table I'!$E$12*100,0) -> 0 | O32: 0 | P32: 0 | Q32: 0 | R32: =$O$32+$P$32+$Q$32 -> 0 | S32: =$R$32+$I$32 -> 0 | T32: =IFERROR(($S$32/'Table I'!$R$12*100),0) -> 0 | U32: 0 | V32: =IFERROR($U$32/$F$32*100,0) -> 0 | W32: 0 | X32: =IFERROR(($W$32/$F$32*100),0) -> 0 | Y32: 0 | Z32: =IFERROR(($Y$32/$F$32*100),0) -> 0 | AA32: 0 | AB32: =IFERROR(($AA$32/$F$32*100),0) -> 0 | AC32: =$W$32+$Y$32+$AA$32 -> 0 | AD32: =IFERROR(($AC$32/$F$32*100),0) -> 0 | AE32: 0
B33: Trust | C33: - | D33: - | E33: 0 | F33: 0 | G33: 0 | H33: 0 | I33: =$F$33+$G$33+$H$33 -> 0 | J33: =IFERROR($I$33/'Table I'!$E$12*100,0) -> 0 | K33: =$I$33 -> 0 | L33: 0 | M33: =$K$33+$L$33 -> 0 | N33: =IFERROR($M$33/'Table I'!$E$12*100,0) -> 0 | O33: 0 | P33: 0 | Q33: 0 | R33: =$O$33+$P$33+$Q$33 -> 0 | S33: =$R$33+$I$33 -> 0 | T33: =IFERROR(($S$33/'Table I'!$R$12*100),0) -> 0 | U33: 0 | V33: =IFERROR($U$33/$F$33*100,0) -> 0 | W33: 0 | X33: =IFERROR(($W$33/$F$33*100),0) -> 0 | Y33: 0 | Z33: =IFERROR(($Y$33/$F$33*100),0) -> 0 | AA33: 0 | AB33: =IFERROR(($AA$33/$F$33*100),0) -> 0 | AC33: =$W$33+$Y$33+$AA$33 -> 0 | AD33: =IFERROR(($AC$33/$F$33*100),0) -> 0 | AE33: 0
B34: Venture Capital Fund | C34: - | D34: - | E34: 0 | F34: 0 | G34: 0 | H34: 0 | I34: =$F$34+$G$34+$H$34 -> 0 | J34: =IFERROR($I$34/'Table I'!$E$12*100,0) -> 0 | K34: =$I$34 -> 0 | L34: 0 | M34: =$K$34+$L$34 -> 0 | N34: =IFERROR($M$34/'Table I'!$E$12*100,0) -> 0 | O34: 0 | P34: 0 | Q34: 0 | R34: =$O$34+$P$34+$Q$34 -> 0 | S34: =$R$34+$I$34 -> 0 | T34: =IFERROR(($S$34/'Table I'!$R$12*100),0) -> 0 | U34: 0 | V34: =IFERROR($U$34/$F$34*100,0) -> 0 | W34: 0 | X34: =IFERROR(($W$34/$F$34*100),0) -> 0 | Y34: 0 | Z34: =IFERROR(($Y$34/$F$34*100),0) -> 0 | AA34: 0 | AB34: =IFERROR(($AA$34/$F$34*100),0) -> 0 | AC34: =$W$34+$Y$34+$AA$34 -> 0 | AD34: =IFERROR(($AC$34/$F$34*100),0) -> 0 | AE34: 0
B35: Sub. Total (A)(2) | C35: - | D35: - | E35: =$E$24+$E$23+$E$22+$E$21+$E$20 -> 0 | F35: =$F$24+$F$23+$F$22+$F$21+$F$20 -> 0 | G35: =$G$20+$G$21+$G$22+$G$23+$G$24 -> 0 | H35: =$H$20+$H$21+$H$22+$H$23+$H$24 -> 0 | I35: =$F$35+$G$35+$H$35 -> 0 | J35: =IFERROR($I$35/'Table I'!$E$12*100,0) -> 0 | K35: =$I$35 -> 0 | L35: 0 | M35: =$K$35+$L$35 -> 0 | N35: =IFERROR($M$35/'Table I'!$E$12*100,0) -> 0 | O35: =$O$20+$O$21+$O$22+$O$23+$O$24 -> 0 | P35: =$P$20+$P$21+$P$22+$P$23+$P$24 -> 0 | Q35: =$Q$20+$Q$21+$Q$22+$Q$23+$Q$24 -> 0 | R35: =$O$35+$P$35+$Q$35 -> 0 | S35: =$R$35+$I$35 -> 0 | T35: =IFERROR(($S$35/'Table I'!$R$12*100),0) -> 0 | U35: =$U$24+$U$23+$U$22+$U$21+$U$20 -> 0 | V35: =IFERROR($U$35/$F$35*100,0) -> 0 | W35: =$W$20+$W$21+$W$22+$W$23+$W$24 -> 0 | X35: =IFERROR(($W$35/$F$35*100),0) -> 0 | Y35: =$Y$20+$Y$21+$Y$22+$Y$23+$Y$24 -> 0 | Z35: =IFERROR(($Y$35/$F$35*100),0) -> 0 | AA35: =$AA$20+$AA$21+$AA$22+$AA$23+$AA$24 -> 0 | AB35: =IFERROR(($AA$35/$F$35*100),0) -> 0 | AC35: =$W$35+$Y$35+$AA$35 -> 0 | AD35: =IFERROR(($AC$35/$F$35*100),0) -> 0 | AE35: =$AE$24+$AE$23+$AE$22+$AE$21+$AE$20 -> 0
B36: Total Shareholding of Promoter and Promoter Group (A)= (A)(1)+(A)(2) | C36: - | D36: - | E36: =$E$35+$E$18 -> 0 | F36: =$F$35+$F$18 -> 0 | G36: =$G$35+$G$18 -> 0 | H36: =$H$35+$H$18 -> 0 | I36: =$H$36+$G$36+$F$36 -> 0 | J36: =IFERROR($I$36/'Table I'!$E$12*100,0) -> 0 | K36: =$I$36 -> 0 | L36: 0 | M36: =$K$36+$L$36 -> 0 | N36: =IFERROR($M$36/'Table I'!$E$12*100,0) -> 0 | O36: =$O$18+$O$35 -> 0 | P36: =$P$18+$P$35 -> 0 | Q36: =$Q$18+$Q$35 -> 0 | R36: =$O$36+$P$36+$Q$36 -> 0 | S36: =$R$36+$I$36 -> 0 | T36: =IFERROR(($S$36/'Table I'!$R$12*100),0) -> 0 | U36: =$U$35+$U$18 -> 0 | V36: =IFERROR($U$36/$F$36*100,0) -> 0 | W36: =$W$35+$W$18 -> 0 | X36: =IFERROR(($W$36/$F$36*100),0) -> 0 | Y36: =$Y$35+$Y$18 -> 0 | Z36: =IFERROR(($Y$36/$F$36*100),0) -> 0 | AA36: =$AA$35+$AA$18 -> 0 | AB36: =IFERROR(($AA$36/$F$36*100),0) -> 0 | AC36: =$W$36+$Y$36+$AA$36 -> 0 | AD36: =IFERROR(($AC$36/$F$36*100),0) -> 0 | AE36: =$AE$35+$AE$18 -> 0
A38: Details of Shares which remain unclaimed may be given here alongwith details such as number of shareholders, outstanding shares held in demat / unclaimed suspense account voting rights which are frozen etc.
A40: Note
A41: 1 | B41: PAN would not be displyed on website of Stock Exchnage(s)
A42: 2 | B42: The above format needs to be diclosed alongwith the name of following pesons- Institutions/ Non Institutions holding more than 1% of the total nunber of shares.
A43: 3 | B43: With respect to the information pertaining to Depository Receipts, the same may be disclosed in the respective columns to the extent information available and the balance to be disclosed as held custodian.

Sheet Table II-A
A1: Details of Shares which remain unclaimed for Promoter & Promoter Group
B3: Sr. No. | C3: Number of shareholders | D3: Outstanding shares held in demat or unclaimed suspense account | E3: Voting rights which are frozen | F3: Disclosure of notes on shares which remain unclaimed for promoter and promoter group
B4: 1 | C4: NIL | D4: NIL | E4: NIL | F4: NIL

Sheet Table III
A1: Table III - Statement showing shareholding pattern of the Public shareholder
A3: (B) | B3: Category & Name of shareholders | C3: PAN | D3: No. of Shareholders | E3: No. of Fully paid up equity shares held | F3: Partly paid-up equity shares held | G3: No. of shares underlying Depository Receipts | H3: Total nos. shares held | I3: Shareholding as a % of total no. of shares (calculated as per SCRR, 1957) | J3: Number of Voting Rights held in each class of securities | N3: No. Of Shares Underlying Outstanding convertible securities | O3: No. of Shares Underlying Outstanding Warrants | P3: No. Of Outstanding ESOP Granted | Q3: No. of Shares Underlying Outstanding convertible securities, No. of Warrants and ESOP etc. | R3: Total No. of shares on fully diluted basis (including warrants, ESOP, Convertible Securities etc.) | S3: Shareholding , as a % assuming full conversion of convertible securities ( as a percentage of diluted share capital) | T3: Number of Locked in shares | V3: Number of Shares pledged | X3: Non-Disposal Undertaking | Z3: Other encumbrances, if any | AB3: Total Number of Shares encumbered | AD3: Number of equity shares held in dematerialized form | AE3: Sub-categorization of shares (XIX)
J4: No. of Voting Rights | M4: Total as a % of Total Voting Rights | T4: No. (a) | U4: As a % of total shares held (b) | V4: No. (a) | W4: As a % of total shares held (b) | X4: No. (a) | Y4: As a % of total shares held (b) | Z4: No. (a) | AA4: As a % of total shares held (b) | AB4: No. (a) | AC4: As a % of total shares held (b) | AE4: Shareholding (No. of shares) under
J5: Class : e.g. X | K5: Class : e.g. Y | L5: Total | AE5: Sub-category (i) | AF5: Sub-category (ii) | AG5: Sub-category (iii)
B6: (I) | C6: (II) | D6: (III) | E6: (IV) | F6: (V) | G6: (VI) | H6: (VII) = (IV)+(V)+ (VI) | I6: (VIII) As a % of (A+B+C2) | J6: (IX) | N6: (XA) | O6: (XB) | P6: (XC) | Q6: (X) = (XA+XB+XC) | R6: (XI)=(VII+X) | S6: (XII)= (VII)+(X) As a % of (A+B+C2) | T6: (XIII) | V6: (XIV) | X6: (XV) | Z6: (XVI) | AB6: (XVII) = (XIV+XV+XVI) | AD6: (XVIII)
A7: ( 1 ) | B7: Institutions (Domestic)
A8: (a) | B8: Mutual Funds | C8: - | D8: 0 | E8: 0 | F8: 0 | G8: 0 | H8: =$E$8+$F$8+$G$8 -> 0 | I8: =IFERROR($H$8/'Table I'!$E$12*100,0) -> 0 | J8: =$H$8 -> 0 | K8: 0 | L8: =$J$8+$K$8 -> 0 | M8: =IFERROR($L$8/'Table I'!$E$12*100,0) -> 0 | N8: 0 | O8: 0 | P8: 0 | Q8: =$P$8+$O$8+$N$8 -> 0 | R8: =$Q$8+$H$8 -> 0 | S8: =IFERROR(($R$8/('Table I'!$R$12)*100),0) -> 0 | T8: 0 | U8: =IFERROR($T$8/$E$8*100,0) -> 0 | AD8: 0 | AE8: 0 | AF8: 0 | AG8: 0
A9: (b) | B9: Venture Capital Funds | C9: - | D9: 0 | E9: 0 | F9: 0 | G9: 0 | H9: =$E$9+$F$9+$G$9 -> 0 | I9: =IFERROR($H$9/'Table I'!$E$12*100,0) -> 0 | J9: =$H$9 -> 0 | K9: 0 | L9: =$J$9+$K$9 -> 0 | M9: =IFERROR($L$9/'Table I'!$E$12*100,0) -> 0 | N9: 0 | O9: 0 | P9: 0 | Q9: =$P$9+$O$9+$N$9 -> 0 | R9: =$Q$9+$H$9 -> 0 | S9: =IFERROR(($R$9/('Table I'!$R$12)*100),0) -> 0 | T9: 0 | U9: =IFERROR($T$9/$E$9*100,0) -> 0 | AD9: 0 | AE9: 0 | AF9: 0 | AG9: 0
A10: (c) | B10: Alternate Investment Funds | C10: - | D10: 0 | E10: 0 | F10: 0 | G10: 0 | H10: =$E$10+$F$10+$G$10 -> 0 | I10: =IFERROR($H$10/'Table I'!$E$12*100,0) -> 0 | J10: =$H$10 -> 0 | K10: 0 | L10: =$J$10+$K$10 -> 0 | M10: =IFERROR($L$10/'Table I'!$E$12*100,0) -> 0 | N10: 0 | O10: 0 | P10: 0 | Q10: =$P$10+$O$10+$N$10 -> 0 | R10: =$Q$10+$H$10 -> 0 | S10: =IFERROR(($R$10/('Table I'!$R$12)*100),0) -> 0 | T10: 0 | U10: =IFERROR($T$10/$E$10*100,0) -> 0 | AD10: 0 | AE10: 0 | AF10: 0 | AG10: 0
A11: (d) | B11: Banks | C11: - | D11: 0 | E11: 0 | F11: 0 | G11: 0 | H11: =$E$11+$F$11+$G$11 -> 0 | I11: =IFERROR($H$11/'Table I'!$E$12*100,0) -> 0 | J11: =$H$11 -> 0 | K11: 0 | L11: =$J$11+$K$11 -> 0 | M11: =IFERROR($L$11/'Table I'!$E$12*100,0) -> 0 | N11: 0 | O11: 0 | P11: 0 | Q11: =$P$11+$O$11+$N$11 -> 0 | R11: =$Q$11+$H$11 -> 0 | S11: =IFERROR(($R$11/('Table I'!$R$12)*100),0) -> 0 | T11: 0 | U11: =IFERROR($T$11/$E$11*100,0) -> 0 | AD11: 0 | AE11: 0 | AF11: 0 | AG11: 0
A12: (e) | B12: Insurance Companies | C12: - | D12: 0 | E12: 0 | F12: 0 | G12: 0 | H12: =$E$12+$F$12+$G$12 -> 0 | I12: =IFERROR($H$12/'Table I'!$E$12*100,0) -> 0 | J12: =$H$12 -> 0 | K12: 0 | L12: =$J$12+$K$12 -> 0 | M12: =IFERROR($L$12/'Table I'!$E$12*100,0) -> 0 | N12: 0 | O12: 0 | P12: 0 | Q12: =$P$12+$O$12+$N$12 -> 0 | R12: =$Q$12+$H$12 -> 0 | S12: =IFERROR(($R$12/('Table I'!$R$12)*100),0) -> 0 | T12: 0 | U12: =IFERROR($T$12/$E$12*100,0) -> 0 | AD12: 0 | AE12: 0 | AF12: 0 | AG12: 0
A13: (f) | B13: Provident Funds/ Pension Funds | C13: - | D13: 0 | E13: 0 | F13: 0 | G13: 0 | H13: =$E$13+$F$13+$G$13 -> 0 | I13: =IFERROR($H$13/'Table I'!$E$12*100,0) -> 0 | J13: =$H$13 -> 0 | K13: 0 | L13: =$J$13+$K$13 -> 0 | M13: =IFERROR($L$13/'Table I'!$E$12*100,0) -> 0 | N13: 0 | O13: 0 | P13: 0 | Q13: =$P$13+$O$13+$N$13 -> 0 | R13: =$Q$13+$H$13 -> 0 | S13: =IFERROR(($R$13/('Table I'!$R$12)*100),0) -> 0 | T13: 0 | U13: =IFERROR($T$13/$E$13*100,0) -> 0 | AD13: 0 | AE13: 0 | AF13: 0 | AG13: 0
A14: (g) | B14: Asset reconstruction companies | C14: - | D14: 0 | E14: 0 | F14: 0 | G14: 0 | H14: =$E$14+$F$14+$G$14 -> 0 | I14: =IFERROR($H$14/'Table I'!$E$12*100,0) -> 0 | J14: =$H$14 -> 0 | K14: 0 | L14: =$J$14+$K$14 -> 0 | M14: =IFERROR($L$14/'Table I'!$E$12*100,0) -> 0 | N14: 0 | O14: 0 | P14: 0 | Q14: =$P$14+$O$14+$N$14 -> 0 | R14: =$Q$14+$H$14 -> 0 | S14: =IFERROR(($R$14/('Table I'!$R$12)*100),0) -> 0 | T14: 0 | U14: =IFERROR($T$14/$E$14*100,0) -> 0 | AD14: 0 | AE14: 0 | AF14: 0 | AG14: 0
A15: (h) | B15: Sovereign Wealth Funds | C15: - | D15: 0 | E15: 0 | F15: 0 | G15: 0 | H15: =$E$15+$F$15+$G$15 -> 0 | I15: =IFERROR($H$15/'Table I'!$E$12*100,0) -> 0 | J15: =$H$15 -> 0 | K15: 0 | L15: =$J$15+$K$15 -> 0 | M15: =IFERROR($L$15/'Table I'!$E$12*100,0) -> 0 | N15: 0 | O15: 0 | P15: 0 | Q15: =$P$15+$O$15+$N$15 -> 0 | R15: =$Q$15+$H$15 -> 0 | S15: =IFERROR(($R$15/('Table I'!$R$12)*100),0) -> 0 | T15: 0 | U15: =IFERROR($T$15/$E$15*100,0) -> 0 | AD15: 0 | AE15: 0 | AF15: 0 | AG15: 0
A16: (i) | B16: NBFCs registered with RBI | C16: - | D16: 0 | E16: 0 | F16: 0 | G16: 0 | H16: =$E$16+$F$16+$G$16 -> 0 | I16: =IFERROR($H$16/'Table I'!$E$12*100,0) -> 0 | J16: =$H$16 -> 0 | K16: 0 | L16: =$J$16+$K$16 -> 0 | M16: =IFERROR($L$16/'Table I'!$E$12*100,0) -> 0 | N16: 0 | O16: 0 | P16: 0 | Q16: =$P$16+$O$16+$N$16 -> 0 | R16: =$Q$16+$H$16 -> 0 | S16: =IFERROR(($R$16/('Table I'!$R$12)*100),0) -> 0 | T16: 0 | U16: =IFERROR($T$16/$E$16*100,0) -> 0 | AD16: 0 | AE16: 0 | AF16: 0 | AG16: 0
A17: (j) | B17: Other Financial Institutions | C17: - | D17: 0 | E17: 0 | F17: 0 | G17: 0 | H17: =$E$17+$F$17+$G$17 -> 0 | I17: =IFERROR($H$17/'Table I'!$E$12*100,0) -> 0 | J17: =$H$17 -> 0 | K17: 0 | L17: =$J$17+$K$17 -> 0 | M17: =IFERROR($L$17/'Table I'!$E$12*100,0) -> 0 | N17: 0 | O17: 0 | P17: 0 | Q17: =$P$17+$O$17+$N$17 -> 0 | R17: =$Q$17+$H$17 -> 0 | S17: =IFERROR(($R$17/('Table I'!$R$12)*100),0) -> 0 | T17: 0 | U17: =IFERROR($T$17/$E$17*100,0) -> 0 | AD17: 0 | AE17: 0 | AF17: 0 | AG17: 0
A18: (k) | B18: Any Other (specify) | C18: - | D18: =$D$19+$D$20+$D$21+$D$22+$D$23+$D$24+$D$25+$D$26+$D$27+$D$28 -> 0 | E18: =$E$19+$E$20+$E$21+$E$22+$E$23+$E$24+$E$25+$E$26+$E$27+$E$28 -> 0 | F18: =$F$19+$F$20+$F$21+$F$22+$F$23+$F$24+$F$25+$F$26+$F$27+$F$28 -> 0 | G18: =$G$19+$G$20+$G$21+$G$22+$G$23+$G$24+$G$25+$G$26+$G$27+$G$28 -> 0 | H18: =$E$18+$F$18+$G$18 -> 0 | I18: =IFERROR($H$18/'Table I'!$E$12*100,0) -> 0 | J18: =$H$18 -> 0 | K18: =$K$19+$K$20+$K$21+$K$22+$K$23+$K$24+$K$25+$K$26+$K$27+$K$28 -> 0 | L18: =$J$18+$K$18 -> 0 | M18: =IFERROR($L$18/'Table I'!$E$12*100,0) -> 0 | N18: =$N$19+$N$20+$N$21+$N$22+$N$23+$N$24+$N$25+$N$26+$N$27+$N$28 -> 0 | O18: =$O$19+$O$20+$O$21+$O$22+$O$23+$O$24+$O$25+$O$26+$O$27+$O$28 -> 0 | P18: =$P$19+$P$20+$P$21+$P$22+$P$23+$P$24+$P$25+$P$26+$P$27+$P$28 -> 0 | Q18: =$P$18+$O$18+$N$18 -> 0 | R18: =$Q$18+$H$18 -> 0 | S18: =IFERROR(($R$18/('Table I'!$R$12)*100),0) -> 0 | T18: =$T$19+$T$20+$T$21+$T$22+$T$23+$T$24+$T$25+$T$26+$T$27+$T$28 -> 0 | U18: =IFERROR($T$18/$E$18*100,0) -> 0 | AD18: 0 | AE18: =$AE$19+$AE$20+$AE$21+$AE$22+$AE$23+$AE$24+$AE$25+$AE$26+$AE$27+$AE$28 -> 0 | AF18: =$AF$19+$AF$20+$AF$21+$AF$22+$AF$23+$AF$24+$AF$25+$AF$26+$AF$27+$AF$28 -> 0 | AG18: =$AG$19+$AG$20+$AG$21+$AG$22+$AG$23+$AG$24+$AG$25+$AG$26+$AG$27+$AG$28 -> 0
B19: State industrial development Corporation | C19: - | D19: 0 | E19: 0 | F19: 0 | G19: 0 | H19: =$E$19+$F$19+$G$19 -> 0 | I19: =IFERROR($H$19/'Table I'!$E$12*100,0) -> 0 | J19: =$H$19 -> 0 | K19: 0 | L19: =$J$19+$K$19 -> 0 | M19: =IFERROR($L$19/'Table I'!$E$12*100,0) -> 0 | N19: 0 | O19: 0 | P19: 0 | Q19: =P19+O19+N19 -> 0 | R19: =$Q$19+$H$19 -> 0 | S19: =IFERROR(($R$19/('Table I'!$R$12)*100),0) -> 0 | T19: 0 | U19: =IFERROR(T19/E19*100,0) -> 0 | AD19: 0 | AE19: 0 | AF19: 0 | AG19: 0
B20: National Investment Fund | C20: - | D20: 0 | E20: 0 | F20: 0 | G20: 0 | H20: =$E$20+$F$20+$G$20 -> 0 | I20: =IFERROR($H$20/'Table I'!$E$12*100,0) -> 0 | J20: =$H$20 -> 0 | K20: 0 | L20: =$J$20+$K$20 -> 0 | M20: =IFERROR($L$20/'Table I'!$E$12*100,0) -> 0 | N20: 0 | O20: 0 | P20: 0 | Q20: =P20+O20+N20 -> 0 | R20: =$Q$20+$H$20 -> 0 | S20: =IFERROR(($R$20/('Table I'!$R$12)*100),0) -> 0 | T20: 0 | U20: =IFERROR(T20/E20*100,0) -> 0 | AD20: 0 | AE20: 0 | AF20: 0 | AG20: 0
B21: Bodies Corporate | C21: - | D21: 0 | E21: 0 | F21: 0 | G21: 0 | H21: =$E$21+$F$21+$G$21 -> 0 | I21: =IFERROR($H$21/'Table I'!$E$12*100,0) -> 0 | J21: =$H$21 -> 0 | K21: 0 | L21: =$J$21+$K$21 -> 0 | M21: =IFERROR($L$21/'Table I'!$E$12*100,0) -> 0 | N21: 0 | O21: 0 | P21: 0 | Q21: =P21+O21+N21 -> 0 | R21: =$Q$21+$H$21 -> 0 | S21: =IFERROR(($R$21/('Table I'!$R$12)*100),0) -> 0 | T21: 0 | U21: =IFERROR(T21/E21*100,0) -> 0 | AD21: 0 | AE21: 0 | AF21: 0 | AG21: 0
B22: Clearing Member | C22: - | D22: 0 | E22: 0 | F22: 0 | G22: 0 | H22: =$E$22+$F$22+$G$22 -> 0 | I22: =IFERROR($H$22/'Table I'!$E$12*100,0) -> 0 | J22: =$H$22 -> 0 | K22: 0 | L22: =$J$22+$K$22 -> 0 | M22: =IFERROR($L$22/'Table I'!$E$12*100,0) -> 0 | N22: 0 | O22: 0 | P22: 0 | Q22: =P22+O22+N22 -> 0 | R22: =$Q$22+$H$22 -> 0 | S22: =IFERROR(($R$22/('Table I'!$R$12)*100),0) -> 0 | T22: 0 | U22: =IFERROR(T22/E22*100,0) -> 0 | AD22: 0 | AE22: 0 | AF22: 0 | AG22: 0
B23: Employee Welfare Fund | C23: - | D23: 0 | E23: 0 | F23: 0 | G23: 0 | H23: =$E$23+$F$23+$G$23 -> 0 | I23: =IFERROR($H$23/'Table I'!$E$12*100,0) -> 0 | J23: =$H$23 -> 0 | K23: 0 | L23: =$J$23+$K$23 -> 0 | M23: =IFERROR($L$23/'Table I'!$E$12*100,0) -> 0 | N23: 0 | O23: 0 | P23: 0 | Q23: =P23+O23+N23 -> 0 | R23: =$Q$23+$H$23 -> 0 | S23: =IFERROR(($R$23/('Table I'!$R$12)*100),0) -> 0 | T23: 0 | U23: =IFERROR(T23/E23*100,0) -> 0 | AD23: 0 | AE23: 0 | AF23: 0 | AG23: 0
B24: Overseas Corporate Bodies | C24: - | D24: 0 | E24: 0 | F24: 0 | G24: 0 | H24: =$E$24+$F$24+$G$24 -> 0 | I24: =IFERROR($H$24/'Table I'!$E$12*100,0) -> 0 | J24: =$H$24 -> 0 | K24: 0 | L24: =$J$24+$K$24 -> 0 | M24: =IFERROR($L$24/'Table I'!$E$12*100,0) -> 0 | N24: 0 | O24: 0 | P24: 0 | Q24: =P24+O24+N24 -> 0 | R24: =$Q$24+$H$24 -> 0 | S24: =IFERROR(($R$24/('Table I'!$R$12)*100),0) -> 0 | T24: 0 | U24: =IFERROR(T24/E24*100,0) -> 0 | AD24: 0 | AE24: 0 | AF24: 0 | AG24: 0
B25: Private Equity Fund | C25: - | D25: 0 | E25: 0 | F25: 0 | G25: 0 | H25: =$E$25+$F$25+$G$25 -> 0 | I25: =IFERROR($H$25/'Table I'!$E$12*100,0) -> 0 | J25: =$H$25 -> 0 | K25: 0 | L25: =$J$25+$K$25 -> 0 | M25: =IFERROR($L$25/'Table I'!$E$12*100,0) -> 0 | N25: 0 | O25: 0 | P25: 0 | Q25: =P25+O25+N25 -> 0 | R25: =$Q$25+$H$25 -> 0 | S25: =IFERROR(($R$25/('Table I'!$R$12)*100),0) -> 0 | T25: 0 | U25: =IFERROR(T25/E25*100,0) -> 0 | AD25: 0 | AE25: 0 | AF25: 0 | AG25: 0
B26: Societies | C26: - | D26: 0 | E26: 0 | F26: 0 | G26: 0 | H26: =$E$26+$F$26+$G$26 -> 0 | I26: =IFERROR($H$26/'Table I'!$E$12*100,0) -> 0 | J26: =$H$26 -> 0 | K26: 0 | L26: =$J$26+$K$26 -> 0 | M26: =IFERROR($L$26/'Table I'!$E$12*100,0) -> 0 | N26: 0 | O26: 0 | P26: 0 | Q26: =P26+O26+N26 -> 0 | R26: =$Q$26+$H$26 -> 0 | S26: =IFERROR(($R$26/('Table I'!$R$12)*100),0) -> 0 | T26: 0 | U26: =IFERROR(T26/E26*100,0) -> 0 | AD26: 0 | AE26: 0 | AF26: 0 | AG26: 0
B27: Trust | C27: - | D27: 0 | E27: 0 | F27: 0 | G27: 0 | H27: =$E$27+$F$27+$G$27 -> 0 | I27: =IFERROR($H$27/'Table I'!$E$12*100,0) -> 0 | J27: =$H$27 -> 0 | K27: 0 | L27: =$J$27+$K$27 -> 0 | M27: =IFERROR($L$27/'Table I'!$E$12*100,0) -> 0 | N27: 0 | O27: 0 | P27: 0 | Q27: =P27+O27+N27 -> 0 | R27: =$Q$27+$H$27 -> 0 | S27: =IFERROR(($R$27/('Table I'!$R$12)*100),0) -> 0 | T27: 0 | U27: =IFERROR(T27/E27*100,0) -> 0 | AD27: 0 | AE27: 0 | AF27: 0 | AG27: 0
B28: Other | C28: - | D28: 0 | E28: 0 | F28: 0 | G28: 0 | H28: =$E$28+$F$28+$G$28 -> 0 | I28: =IFERROR($H$28/'Table I'!$E$12*100,0) -> 0 | J28: =$H$28 -> 0 | K28: 0 | L28: =$J$28+$K$28 -> 0 | M28: =IFERROR($L$28/'Table I'!$E$12*100,0) -> 0 | N28: 0 | O28: 0 | P28: 0 | Q28: =P28+O28+N28 -> 0 | R28: =$Q$28+$H$28 -> 0 | S28: =IFERROR(($R$28/('Table I'!$R$12)*100),0) -> 0 | T28: 0 | U28: =IFERROR(T28/E28*100,0) -> 0 | AD28: 0 | AE28: 0 | AF28: 0 | AG28: 0
B29: Sub. Total (B)(1) | C29: - | D29: =$D$18+$D$17+$D$16+$D$15+$D$14+$D$13+$D$12+$D$11+$D$10+$D$9+$D$8 -> 0 | E29: =$E$18+$E$17+$E$16+$E$15+$E$14+$E$13+$E$12+$E$11+$E$10+$E$9+$E$8 -> 0 | F29: =$F$8+$F$9+$F$10+$F$11+$F$12+$F$13+$F$14+$F$15+$F$16+$F$17+$F$18 -> 0 | G29: =$G$8+$G$9+$G$10+$G$11+$G$12+$G$13+$G$14+$G$15+$G$16+$G$17+$G$18 -> 0 | H29: =$E$29+$F$29+$G$29 -> 0 | I29: =IFERROR($H$29/'Table I'!$E$12*100,0) -> 0 | J29: =$H$29 -> 0 | K29: =$K$8+$K$9+$K$10+$K$11+$K$12+$K$13+$K$14+$K$15+$K$16+$K$17+$K$18 -> 0 | L29: =$J$29+$K$29 -> 0 | M29: =IFERROR($L$29/'Table I'!$E$12*100,0) -> 0 | N29: =$N$18+$N$17+$N$16+$N$15+$N$14+$N$13+$N$12+$N$11+$N$10+$N$9+$N$8 -> 0 | O29: =$O$18+$O$17+$O$16+$O$15+$O$14+$O$13+$O$12+$O$11+$O$10+$O$9+$O$8 -> 0 | P29: =$P$18+$P$17+$P$16+$P$15+$P$14+$P$13+$P$12+$P$11+$P$10+$P$9+$P$8 -> 0 | Q29: =$P$29+$O$29+$N$29 -> 0 | R29: =$Q$29+$H$29 -> 0 | S29: =IFERROR(($R$29/('Table I'!$R$12)*100),0) -> 0 | T29: =$T$18+$T$17+$T$16+$T$15+$T$14+$T$13+$T$12+$T$11+$T$10+$T$9+$T$8 -> 0 | U29: =IFERROR($T$29/$E$29*100,0) -> 0 | AD29: =$AD$18+$AD$17+$AD$16+$AD$15+$AD$14+$AD$13+$AD$12+$AD$11+$AD$10+$AD$9+$AD$8 -> 0 | AE29: =$AE$18+$AE$17+$AE$16+$AE$15+$AE$14+$AE$13+$AE$12+$AE$11+$AE$10+$AE$9+$AE$8 -> 0 | AF29: =$AF$18+$AF$17+$AF$16+$AF$15+$AF$14+$AF$13+$AF$12+$AF$11+$AF$10+$AF$9+$AF$8 -> 0 | AG29: =$AG$18+$AG$17+$AG$16+$AG$15+$AG$14+$AG$13+$AG$12+$AG$11+$AG$10+$AG$9+$AG$8 -> 0
A30: ( 2 ) | B30: Institutions (Foreign)
A31: (a) | B31: Foreign Direct Investment | C31: - | D31: 0 | E31: 0 | F31: 0 | G31: 0 | H31: =$E$31+$F$31+$G$31 -> 0 | I31: =IFERROR($H$31/'Table I'!$E$12*100,0) -> 0 | J31: =$H$31 -> 0 | K31: 0 | L31: =$J$31+$K$31 -> 0 | M31: =IFERROR($L$31/'Table I'!$E$12*100,0) -> 0 | N31: 0 | O31: 0 | P31: 0 | Q31: =$N$31+$O$31+$P$31 -> 0 | R31: =$Q$31+$H$31 -> 0 | S31: =IFERROR(($R$31/('Table I'!$R$12)*100),0) -> 0 | T31: 0 | U31: =IFERROR($T$31/$E$31*100,0) -> 0 | AD31: 0 | AE31: 0 | AF31: 0 | AG31: 0
A32: (b) | B32: Foreign Venture Capital Investors | C32: - | D32: 0 | E32: 0 | F32: 0 | G32: 0 | H32: =$E$32+$F$32+$G$32 -> 0 | I32: =IFERROR($H$32/'Table I'!$E$12*100,0) -> 0 | J32: =$H$32 -> 0 | K32: 0 | L32: =$J$32+$K$32 -> 0 | M32: =IFERROR($L$32/'Table I'!$E$12*100,0) -> 0 | N32: 0 | O32: 0 | P32: 0 | Q32: =$N$32+$O$32+$P$32 -> 0 | R32: =$Q$32+$H$32 -> 0 | S32: =IFERROR(($R$32/('Table I'!$R$12)*100),0) -> 0 | T32: 0 | U32: =IFERROR($T$32/$E$32*100,0) -> 0 | AD32: 0 | AE32: 0 | AF32: 0 | AG32: 0
A33: (c) | B33: Sovereign Wealth Funds | C33: - | D33: 0 | E33: 0 | F33: 0 | G33: 0 | H33: =$E$33+$F$33+$G$33 -> 0 | I33: =IFERROR($H$33/'Table I'!$E$12*100,0) -> 0 | J33: =$H$33 -> 0 | K33: 0 | L33: =$J$33+$K$33 -> 0 | M33: =IFERROR($L$33/'Table I'!$E$12*100,0) -> 0 | N33: 0 | O33: 0 | P33: 0 | Q33: =$N$33+$O$33+$P$33 -> 0 | R33: =$Q$33+$H$33 -> 0 | S33: =IFERROR(($R$33/('Table I'!$R$12)*100),0) -> 0 | T33: 0 | U33: =IFERROR($T$33/$E$33*100,0) -> 0 | AD33: 0 | AE33: 0 | AF33: 0 | AG33: 0
A34: (d) | B34: Foreign Portfolio Investors Category I | C34: - | D34: 0 | E34: 0 | F34: 0 | G34: 0 | H34: =$E$34+$F$34+$G$34 -> 0 | I34: =IFERROR($H$34/'Table I'!$E$12*100,0) -> 0 | J34: =$H$34 -> 0 | K34: 0 | L34: =$J$34+$K$34 -> 0 | M34: =IFERROR($L$34/'Table I'!$E$12*100,0) -> 0 | N34: 0 | O34: 0 | P34: 0 | Q34: =$N$34+$O$34+$P$34 -> 0 | R34: =$Q$34+$H$34 -> 0 | S34: =IFERROR(($R$34/('Table I'!$R$12)*100),0) -> 0 | T34: 0 | U34: =IFERROR($T$34/$E$34*100,0) -> 0 | AD34: 0 | AE34: 0 | AF34: 0 | AG34: 0
A35: (e) | B35: Foreign Portfolio Investors Category II | C35: - | D35: 0 | E35: 0 | F35: 0 | G35: 0 | H35: =$E$35+$F$35+$G$35 -> 0 | I35: =IFERROR($H$35/'Table I'!$E$12*100,0) -> 0 | J35: =$H$35 -> 0 | K35: 0 | L35: =$J$35+$K$35 -> 0 | M35: =IFERROR($L$35/'Table I'!$E$12*100,0) -> 0 | N35: 0 | O35: 0 | P35: 0 | Q35: =$N$35+$O$35+$P$35 -> 0 | R35: =$Q$35+$H$35 -> 0 | S35: =IFERROR(($R$35/('Table I'!$R$12)*100),0) -> 0 | T35: 0 | U35: =IFERROR($T$35/$E$35*100,0) -> 0 | AD35: 0 | AE35: 0 | AF35: 0 | AG35: 0
A36: (f) | B36: Overseas Depositories (holding DRs) (balancing figure) | C36: - | D36: 0 | E36: 0 | F36: 0 | G36: 0 | H36: =$E$36+$F$36+$G$36 -> 0 | I36: =IFERROR($H$36/'Table I'!$E$12*100,0) -> 0 | J36: =$H$36 -> 0 | K36: 0 | L36: =$J$36+$K$36 -> 0 | M36: =IFERROR($L$36/'Table I'!$E$12*100,0) -> 0 | N36: 0 | O36: 0 | P36: 0 | Q36: =$N$36+$O$36+$P$36 -> 0 | R36: =$Q$36+$H$36 -> 0 | S36: =IFERROR(($R$36/('Table I'!$R$12)*100),0) -> 0 | T36: 0 | U36: =IFERROR($T$36/$E$36*100,0) -> 0 | AD36: 0 | AE36: 0 | AF36: 0 | AG36: 0
A37: (g) | B37: Any Other (specify) | C37: - | D37: =$D$38+$D$39+$D$40+$D$41+$D$42+$D$43+$D$44+$D$45+$D$46+$D$47+$D$48+$D$49+$D$50+$D$51 -> 0 | E37: =$E$38+$E$39+$E$40+$E$41+$E$42+$E$43+$E$44+$E$45+$E$46+$E$47+$E$48+$E$49+$E$50+$E$51 -> 0 | F37: =$F$38+$F$39+$F$40+$F$41+$F$42+$F$43+$F$44+$F$45+$F$46+$F$47+$F$48+$F$49+$F$50+$F$51 -> 0 | G37: =$G$38+$G$39+$G$40+$G$41+$G$42+$G$43+$G$44+$G$45+$G$46+$G$47+$G$48+$G$49+$G$50+$G$51 -> 0 | H37: =$E$37+$F$37+$G$37 -> 0 | I37: =IFERROR($H$37/'Table I'!$E$12*100,0) -> 0 | J37: =$H$37 -> 0 | K37: =$K$38+$K$39+$K$40+$K$41+$K$42+$K$43+$K$44+$K$45+$K$46+$K$47+$K$48+$K$49+$K$50+$K$51 -> 0 | L37: =$J$37+$K$37 -> 0 | M37: =IFERROR($L$37/'Table I'!$E$12*100,0) -> 0 | N37: =$N$38+$N$39+$N$40+$N$41+$N$42+$N$43+$N$44+$N$45+$N$46+$N$47+$N$48+$N$49+$N$50+$N$51 -> 0 | O37: =$O$38+$O$39+$O$40+$O$41+$O$42+$O$43+$O$44+$O$45+$O$46+$O$47+$O$48+$O$49+$O$50+$O$51 -> 0 | P37: =$P$38+$P$39+$P$40+$P$41+$P$42+$P$43+$P$44+$P$45+$P$46+$P$47+$P$48+$P$49+$P$50+$P$51 -> 0 | Q37: =$N$37+$O$37+$P$37 -> 0 | R37: =$Q$37+$H$37 -> 0 | S37: =IFERROR(($R$37/('Table I'!$R$12)*100),0) -> 0 | T37: =$T$38+$T$39+$T$40+$T$41+$T$42+$T$43+$T$44+$T$45+$T$46+$T$47+$T$48+$T$49+$T$50+$T$51 -> 0 | U37: =IFERROR($T$37/$E$37*100,0) -> 0 | AD37: 0 | AE37: =$AE$38+$AE$39+$AE$40+$AE$41+$AE$42+$AE$43+$AE$44+$AE$45+$AE$46+$AE$47+$AE$48+$AE$49+$AE$50+$AE$51 -> 0 | AF37: =$AF$38+$AF$39+$AF$40+$AF$41+$AF$42+$AF$43+$AF$44+$AF$45+$AF$46+$AF$47+$AF$48+$AF$49+$AF$50+$AF$51 -> 0 | AG37: =$AG$38+$AG$39+$AG$40+$AG$41+$AG$42+$AG$43+$AG$44+$AG$45+$AG$46+$AG$47+$AG$48+$AG$49+$AG$50+$AG$51 -> 0
B38: State industrial development Corporation | C38: - | D38: 0 | E38: 0 | F38: 0 | G38: 0 | H38: =$E$38+$F$38+$G$38 -> 0 | I38: =IFERROR($H$38/'Table I'!$E$12*100,0) -> 0 | J38: =$H$38 -> 0 | K38: 0 | L38: =$J$38+$K$38 -> 0 | M38: =IFERROR($L$38/'Table I'!$E$12*100,0) -> 0 | N38: 0 | O38: 0 | P38: 0 | Q38: =$P$38+$O$38+$N$38 -> 0 | R38: =$Q$38+$H$38 -> 0 | S38: =IFERROR(($R$38/('Table I'!$R$12)*100),0) -> 0 | T38: 0 | U38: =IFERROR($T$38/$E$38*100,0) -> 0 | AD38: 0 | AE38: 0 | AF38: 0 | AG38: 0
B39: Provident Fund | C39: - | D39: 0 | E39: 0 | F39: 0 | G39: 0 | H39: =$E$39+$F$39+$G$39 -> 0 | I39: =IFERROR($H$39/'Table I'!$E$12*100,0) -> 0 | J39: =$H$39 -> 0 | K39: 0 | L39: =$J$39+$K$39 -> 0 | M39: =IFERROR($L$39/'Table I'!$E$12*100,0) -> 0 | N39: 0 | O39: 0 | P39: 0 | Q39: =$P$39+$O$39+$N$39 -> 0 | R39: =$Q$39+$H$39 -> 0 | S39: =IFERROR(($R$39/('Table I'!$R$12)*100),0) -> 0 | T39: 0 | U39: =IFERROR($T$39/$E$39*100,0) -> 0 | AD39: 0 | AE39: 0 | AF39: 0 | AG39: 0
B40: Pension Fund | C40: - | D40: 0 | E40: 0 | F40: 0 | G40: 0 | H40: =$E$40+$F$40+$G$40 -> 0 | I40: =IFERROR($H$40/'Table I'!$E$12*100,0) -> 0 | J40: =$H$40 -> 0 | K40: 0 | L40: =$J$40+$K$40 -> 0 | M40: =IFERROR($L$40/'Table I'!$E$12*100,0) -> 0 | N40: 0 | O40: 0 | P40: 0 | Q40: =$P$40+$O$40+$N$40 -> 0 | R40: =$Q$40+$H$40 -> 0 | S40: =IFERROR(($R$40/('Table I'!$R$12)*100),0) -> 0 | T40: 0 | U40: =IFERROR($T$40/$E$40*100,0) -> 0 | AD40: 0 | AE40: 0 | AF40: 0 | AG40: 0
B41: National Investment Fund | C41: - | D41: 0 | E41: 0 | F41: 0 | G41: 0 | H41: =$E$41+$F$41+$G$41 -> 0 | I41: =IFERROR($H$41/'Table I'!$E$12*100,0) -> 0 | J41: =$H$41 -> 0 | K41: 0 | L41: =$J$41+$K$41 -> 0 | M41: =IFERROR($L$41/'Table I'!$E$12*100,0) -> 0 | N41: 0 | O41: 0 | P41: 0 | Q41: =$P$41+$O$41+$N$41 -> 0 | R41: =$Q$41+$H$41 -> 0 | S41: =IFERROR(($R$41/('Table I'!$R$12)*100),0) -> 0 | T41: 0 | U41: =IFERROR($T$41/$E$41*100,0) -> 0 | AD41: 0 | AE41: 0 | AF41: 0 | AG41: 0
...

Sheet Table III-A
A1: Details of the shareholders acting as persons in Concert for Public
B3: Sr. No. | C3: Name of Shareholder | D3: Name of the PAC | E3: Number of shares | F3: Percentage of shareholding by PAC
B4: 1 | C4: NIL | D4: NIL | E4: NIL | F4: NIL

Sheet Table III-B
A1: Details of Shares which remain unclaimed for Public
B3: Sr. No. | C3: Number of shareholders | D3: Outstanding shares held in demat or unclaimed suspense account | E3: Voting rights which are frozen | F3: Disclosure of notes on shares which remain unclaimed for public shareholders
B4: 1 | C4: NIL | D4: NIL | E4: NIL | F4: NIL

Sheet Table IV
A1: Table IV - Statement showing shareholding pattern of the Non Promoter- Non Public shareholder
A3: (C) | B3: Category & Name of shareholders | C3: PAN | D3: No. of Shareholders | E3: No. of Fully paid up equity shares held | F3: Partly paid-up equity shares held | G3: No. of shares underlying Depository Receipts | H3: Total nos. shares held | I3: Shareholding as a % of total no. of shares (calculated as per SCRR, 1957) | J3: Number of Voting Rights held in each class of securities | N3: No. Of Shares Underlying Outstanding convertible securities | O3: No. of Shares Underlying Outstanding Warrants | P3: No. Of Outstanding ESOP Granted | Q3: No. of Shares Underlying Outstanding convertible securities, No. of Warrants and ESOP etc. | R3: Total No. of shares on fully diluted basis (including warrants, ESOP, Convertible Securities etc.) | S3: Shareholding , as a % assuming full conversion of convertible securities ( as a percentage of diluted share capital) | T3: Number of Locked in shares | V3: Number of Shares pledged | X3: Non-Disposal Undertaking | Z3: Other encumbrances, if any | AB3: Total Number of Shares encumbered | AD3: Number of equity shares held in dematerialized form | AE3: Sub-categorization of shares (XIX)
J4: No. of Voting Rights | M4: Total as a % of Total Voting Rights | T4: No. (a) | U4: As a % of total shares held (b) | V4: No. (a) | W4: As a % of total shares held (b) | X4: No. (a) | Y4: As a % of total shares held (b) | Z4: No. (a) | AA4: As a % of total shares held (b) | AB4: No. (a) | AC4: As a % of total shares held (b) | AE4: Shareholding (No. of shares) under
J5: Class : e.g. X | K5: Class : e.g. Y | L5: Total | AE5: Sub-category (i) | AF5: Sub-category (ii) | AG5: Sub-category (iii)
B6: (I) | C6: (II) | D6: (III) | E6: (IV) | F6: (V) | G6: (VI) | H6: (VII) = (IV)+(V)+ (VI) | I6: (VIII) As a % of (A+B+C2) | J6: (IX) | N6: (XA) | O6: (XB) | P6: (XC) | Q6: (X) = (XA+XB+XC) | R6: (XI)=(VII+X) | S6: (XII)= (VII)+(X) As a % of (A+B+C2) | T6: (XIII) | V6: (XIV) | X6: (XV) | Z6: (XVI) | AB6: (XVII) = (XIV+XV+XVI) | AD6: (XVIII)
A7: ( 1 ) | B7: Custodian/DR Holder | C7: - | D7: 0 | E7: 0 | F7: 0 | G7: 0 | H7: =E7+F7+G7 -> 0 | J7: =H7 -> 0 | K7: 0 | L7: =J7+K7 -> 0 | M7: =IFERROR(L7/'Table I'!$E$12*100,0) -> 0 | N7: 0 | O7: 0 | P7: 0 | Q7: =P7+O7+N7 -> 0 | R7: =Q7+H7 -> 0 | T7: 0 | U7: =IFERROR(T7/E7*100,0) -> 0 | AD7: =E7 -> 0
A8: ( 2 ) | B8: Employees Benefit Trust (Under SEBI (Share Based Employee Benefit Regulation 2014) | C8: - | D8: 0 | E8: 0 | F8: 0 | G8: 0 | H8: =E8+F8+G8 -> 0 | I8: =IFERROR(H8/'Table I'!$E$12*100,0) -> 0 | J8: =H8 -> 0 | K8: 0 | L8: =J8+K8 -> 0 | M8: =IFERROR(L8/'Table I'!$E$12*100,0) -> 0 | N8: 0 | O8: 0 | P8: 0 | Q8: =P8+O8+N8 -> 0 | R8: =Q8+H8 -> 0 | S8: =IFERROR((R8/('Table I'!$R$12)*100),0) -> 0 | T8: 0 | U8: =IFERROR(T8/E8*100,0) -> 0 | AD8: =E8 -> 0 | AE8: 0 | AF8: 0 | AG8: 0
B9: Total Non Promoter Non Public Shareholding (C)= (C)(1)+(C)(2) | C9: - | D9: =$D$8+$D$7 -> 0 | E9: =$E$8+$E$7 -> 0 | F9: 0 | G9: 0 | H9: =$E$9 -> 0 | J9: =$L$9 -> 0 | K9: 0 | L9: =$H$9 -> 0 | M9: =$I$9 -> 0 | N9: =$N$8+$N$7 -> 0 | O9: =$O$8+$O$7 -> 0 | P9: =$P$8+$P$7 -> 0 | Q9: =$P$9+$O$9+$N$9 -> 0 | R9: =$Q$9+$H$9 -> 0 | T9: =$T$8+$T$7 -> 0 | U9: =IFERROR($T$9/$E$9*100,0) -> 0 | AD9: =$AD$8+$AD$7 -> 0

Sheet Table V
A2: Table V - Statement showing details of significant beneficial owners
A4: Sr. No | B4: Details of the beneficial owner (I) | E4: Details of the registered owner (II) | H4: Particulars of the shares in which significant beneficial interest is held by the beneficial owner (III) | J4: Date of Creation / acquisition of significant beneficial interest (IV)
B5: NAME | C5: PAN | D5: Nationality | E5: Name | F5: PAN | G5: Nationality | H5: Number of shares | I5: Shareholding as a % of total no. of shares (calculated as per SCRR, 1957) As a % of (A+B+C2)
A6: NIL | B6: NIL | C6: NIL | D6: NIL | E6: NIL | F6: NIL | G6: NIL | H6: NIL | I6: NIL | J6: NIL

Sheet Annexure B
A1: Annexure B
A2: Table VI - Statement showing foreign ownership limits
B4: Particulars | C4: Board approved limits % | D4: Limits utilized %
B5: As on shareholding date | C5: 100 | D5: 0
B6: As on the end of previous 1st quarter | C6: 100 | D6: 0
B7: As on the end of previous 2nd quarter | C7: 100 | D7: 0
B8: As on the end of previous 3rd quarter | C8: 100 | D8: 0
B9: As on the end of previous 4th quarter | C9: 100 | D9: 0

Sheet Annexure A
A1: Annexure A
A2: List of Promoter/Promoter Group having - Zero/NIL Holding in company
A4: S.No. | B4: Name | C4: PAN | D4: Category | E4: Type
